<?xml version="1.0"?>
<robot name="humanoid">

  <!-- Base Link (Torso) -->
  <link name="torso">
    <visual>
      <geometry>
        <box size="0.2 0.1 0.4"/>
      </geometry>
      <material name="blue">
        <color rgba="0 0 0.8 1"/>
      </material>
    </visual>
  </link>

  <!-- Head Link -->
  <link name="head">
    <visual>
      <geometry>
        <sphere radius="0.1"/>
      </geometry>
      <material name="red">
        <color rgba="0.8 0 0 1"/>
      </material>
    </visual>
  </link>

  <!-- Neck Joint (Torso to Head) -->
  <joint name="neck_joint" type="revolute">
    <parent link="torso"/>
    <child link="head"/>
    <origin xyz="0 0 0.25" rpy="0 0 0"/>
    <axis xyz="0 0 1"/>
    <limit lower="-1.57" upper="1.57" effort="100" velocity="0.5"/>
  </joint>

  <!-- Left Arm Link -->
  <link name="left_arm">
    <visual>
      <geometry>
        <cylinder radius="0.05" length="0.3"/>
      </geometry>
      <material name="green">
        <color rgba="0 0.8 0 1"/>
      </material>
    </visual>
  </link>

  <!-- Left Shoulder Joint (Torso to Left Arm) -->
  <joint name="left_shoulder_joint" type="revolute">
    <parent link="torso"/>
    <child link="left_arm"/>
    <origin xyz="0 0.05 0.1" rpy="0 0 0"/>
    <axis xyz="0 1 0"/>
    <limit lower="-1.57" upper="1.57" effort="100" velocity="0.5"/>
  </joint>

  <!-- Right Arm Link -->
  <link name="right_arm">
    <visual>
      <geometry>
        <cylinder radius="0.05" length="0.3"/>
      </geometry>
      <material name="green"/>
    </visual>
  </link>

  <!-- Right Shoulder Joint (Torso to Right Arm) -->
  <joint name="right_shoulder_joint" type="revolute">
    <parent link="torso"/>
    <child link="right_arm"/>
    <origin xyz="0 -0.05 0.1" rpy="0 0 0"/>
    <axis xyz="0 1 0"/>
    <limit lower="-1.57" upper="1.57" effort="100" velocity="0.5"/>
  </joint>

</robot>
